2022-12-29 10:30:50,345 INFO    StreamThr :56296 [internal.py:wandb_internal():87] W&B internal server running at pid: 56296, started at: 2022-12-29 10:30:50.343876
2022-12-29 10:30:50,346 DEBUG   HandlerThread:56296 [handler.py:handle_request():139] handle_request: status
2022-12-29 10:30:50,352 DEBUG   SenderThread:56296 [sender.py:send_request():317] send_request: status
2022-12-29 10:30:50,376 INFO    WriterThread:56296 [datastore.py:open_for_write():75] open: C:\Users\zaome\Documents\Projet_Fil_Rouge\Application\wandb\run-20221229_103050-3ecdtp6y\run-3ecdtp6y.wandb
2022-12-29 10:30:50,376 DEBUG   SenderThread:56296 [sender.py:send():303] send: header
2022-12-29 10:30:50,471 DEBUG   SenderThread:56296 [sender.py:send():303] send: run
2022-12-29 10:30:50,875 ERROR   SenderThread:56296 [internal_api.py:execute():212] 401 response executing GraphQL.
2022-12-29 10:30:50,875 ERROR   SenderThread:56296 [internal_api.py:execute():213] {"errors":[{"message":"user is not logged in","path":["upsertBucket"],"extensions":{"code":"PERMISSION_ERROR"}}],"data":{"upsertBucket":null}}
2022-12-29 10:30:51,482 INFO    WriterThread:56296 [datastore.py:close():279] close: C:\Users\zaome\Documents\Projet_Fil_Rouge\Application\wandb\run-20221229_103050-3ecdtp6y\run-3ecdtp6y.wandb
2022-12-29 10:30:51,482 INFO    HandlerThread:56296 [handler.py:finish():814] shutting down handler
2022-12-29 10:30:51,483 ERROR   StreamThr :56296 [internal.py:wandb_internal():162] Thread SenderThread:
Traceback (most recent call last):
  File "C:\Users\zaome\.virtualenvs\Application-5xQfdT23\lib\site-packages\wandb\sdk\lib\retry.py", line 113, in __call__
    result = self._call_fn(*args, **kwargs)
  File "C:\Users\zaome\.virtualenvs\Application-5xQfdT23\lib\site-packages\wandb\sdk\internal\internal_api.py", line 209, in execute
    return self.client.execute(*args, **kwargs)  # type: ignore
  File "C:\Users\zaome\.virtualenvs\Application-5xQfdT23\lib\site-packages\wandb\vendor\gql-0.2.0\wandb_gql\client.py", line 52, in execute
    result = self._get_result(document, *args, **kwargs)
  File "C:\Users\zaome\.virtualenvs\Application-5xQfdT23\lib\site-packages\wandb\vendor\gql-0.2.0\wandb_gql\client.py", line 60, in _get_result
    return self.transport.execute(document, *args, **kwargs)
  File "C:\Users\zaome\.virtualenvs\Application-5xQfdT23\lib\site-packages\wandb\vendor\gql-0.2.0\wandb_gql\transport\requests.py", line 39, in execute
    request.raise_for_status()
  File "C:\Users\zaome\.virtualenvs\Application-5xQfdT23\lib\site-packages\requests\models.py", line 1021, in raise_for_status
    raise HTTPError(http_error_msg, response=self)
requests.exceptions.HTTPError: 401 Client Error: Unauthorized for url: https://api.wandb.ai/graphql

During handling of the above exception, another exception occurred:

Traceback (most recent call last):
  File "C:\Users\zaome\.virtualenvs\Application-5xQfdT23\lib\site-packages\wandb\apis\normalize.py", line 26, in wrapper
    return func(*args, **kwargs)
  File "C:\Users\zaome\.virtualenvs\Application-5xQfdT23\lib\site-packages\wandb\sdk\internal\internal_api.py", line 1515, in upsert_run
    response = self.gql(
  File "C:\Users\zaome\.virtualenvs\Application-5xQfdT23\lib\site-packages\wandb\sdk\lib\retry.py", line 129, in __call__
    retry_timedelta_triggered = check_retry_fn(e)
  File "C:\Users\zaome\.virtualenvs\Application-5xQfdT23\lib\site-packages\wandb\util.py", line 1044, in check_retry_fn
    return fallback_retry_fn(e)
  File "C:\Users\zaome\.virtualenvs\Application-5xQfdT23\lib\site-packages\wandb\util.py", line 987, in no_retry_auth
    raise CommError("Invalid or missing api_key. Run `wandb login`")
wandb.errors.CommError: Invalid or missing api_key. Run `wandb login`

During handling of the above exception, another exception occurred:

Traceback (most recent call last):
  File "C:\Users\zaome\.virtualenvs\Application-5xQfdT23\lib\site-packages\wandb\sdk\internal\internal_util.py", line 49, in run
    self._run()
  File "C:\Users\zaome\.virtualenvs\Application-5xQfdT23\lib\site-packages\wandb\sdk\internal\internal_util.py", line 100, in _run
    self._process(record)
  File "C:\Users\zaome\.virtualenvs\Application-5xQfdT23\lib\site-packages\wandb\sdk\internal\internal.py", line 309, in _process
    self._sm.send(record)
  File "C:\Users\zaome\.virtualenvs\Application-5xQfdT23\lib\site-packages\wandb\sdk\internal\sender.py", line 305, in send
    send_handler(record)
  File "C:\Users\zaome\.virtualenvs\Application-5xQfdT23\lib\site-packages\wandb\sdk\internal\sender.py", line 797, in send_run
    self._init_run(run, config_value_dict)
  File "C:\Users\zaome\.virtualenvs\Application-5xQfdT23\lib\site-packages\wandb\sdk\internal\sender.py", line 823, in _init_run
    server_run, inserted, server_messages = self._api.upsert_run(
  File "C:\Users\zaome\.virtualenvs\Application-5xQfdT23\lib\site-packages\wandb\apis\normalize.py", line 62, in wrapper
    raise CommError(message, err).with_traceback(sys.exc_info()[2])
  File "C:\Users\zaome\.virtualenvs\Application-5xQfdT23\lib\site-packages\wandb\apis\normalize.py", line 26, in wrapper
    return func(*args, **kwargs)
  File "C:\Users\zaome\.virtualenvs\Application-5xQfdT23\lib\site-packages\wandb\sdk\internal\internal_api.py", line 1515, in upsert_run
    response = self.gql(
  File "C:\Users\zaome\.virtualenvs\Application-5xQfdT23\lib\site-packages\wandb\sdk\lib\retry.py", line 129, in __call__
    retry_timedelta_triggered = check_retry_fn(e)
  File "C:\Users\zaome\.virtualenvs\Application-5xQfdT23\lib\site-packages\wandb\util.py", line 1044, in check_retry_fn
    return fallback_retry_fn(e)
  File "C:\Users\zaome\.virtualenvs\Application-5xQfdT23\lib\site-packages\wandb\util.py", line 987, in no_retry_auth
    raise CommError("Invalid or missing api_key. Run `wandb login`")
wandb.errors.CommError: Invalid or missing api_key. Run `wandb login`
